Workbook
Name TB_ALIMENTO_ANALITO_2: 'IBGE - 2011'!#REF!
Name TB_ALIMENTO_ANALITO_2: IBGE_2!$C$2:$AG$1948

Sheet TACO v. 2 - 2006
A1: Descrição do alimento | B1: Quantidade (g) | C1: Energia (kcal) | D1: Proteína (g) | E1: Lipídeos (g) | F1: Saturada (g) | G1: Monoinsat (g) | H1: Polinsat (g) | I1: ômega 6 | J1: ômega 3 | K1: Colesterol (mg) | L1: CHO (g) | M1: Fibras (g) | N1: Cálcio (mg) | O1: Mg (mg) | P1: Mn (mg) | Q1: P (mg) | R1: Ferro (mg) | S1: Sódio (mg) | T1: Potássio (mg) | U1: Cobre (mg) | V1: Zinco (mg) | W1: Retinol (mcg) | X1: Tiamina (mg) | Y1: Riboflavina (mg) | Z1: Piridoxina (mg) | AA1: Niacina (mg) | AB1: Vit. C (mg)
A2: Cereais e derivados
A3: Arroz, integral, cozido | B3: 100 | C3: =B3*124/100 -> 124 | D3: =B3*2.6/100 -> 2.6 | E3: =B3*1/100 -> 1 | F3: =B3*0.3/100 -> 0.3 | G3: =B3*0.4/100 -> 0.4 | H3: =B3*0.3/100 -> 0.3 | I3: =B3*0.31/100 -> 0.31 | J3: =B3*0.01/100 -> 0.01 | K3: NA | L3: =B3*25.8/100 -> 25.8 | M3: =B3*2.7/100 -> 2.7 | N3: =B3*5/100 -> 5 | O3: =B3*59/100 -> 59 | P3: =B3*0.63/100 -> 0.63 | Q3: =B3*106/100 -> 106 | R3: =B3*0.3/100 -> 0.3 | S3: =B3*1/100 -> 1 | T3: =B3*75/100 -> 75 | U3: =B3*0.02/100 -> 0.02 | V3: =B3*0.7/100 -> 0.7 | W3: NA | X3: =B3*0.08/100 -> 0.08 | Y3: Tr | Z3: =B3*0.08/100 -> 0.08 | AA3: Tr
A4: Arroz, integral, cru | B4: 100 | C4: =B4*360/100 -> 360 | D4: =B4*7.3/100 -> 7.3 | E4: =B4*1.9/100 -> 1.9 | F4: =B4*0.3/100 -> 0.3 | G4: =B4*0.5/100 -> 0.5 | H4: =B4*0.4/100 -> 0.4 | I4: =B4*0.38/100 -> 0.38 | J4: =B4*0.02/100 -> 0.02 | K4: NA | L4: =B4*77.5/100 -> 77.5 | M4: =B4*4.8/100 -> 4.8 | N4: =B4*8/100 -> 8 | O4: =B4*110/100 -> 110 | P4: =B4*2.9/100 -> 2.9 | Q4: =B4*251/100 -> 251 | R4: =B4*0.9/100 -> 0.9 | S4: =B4*2/100 -> 2 | T4: =B4*1173/100 -> 1173 | U4: =B4*0.07/100 -> 0.07 | V4: =B4*1.4/100 -> 1.4 | W4: NA | X4: =B4*0.26/100 -> 0.26 | Y4: Tr | Z4: =B4*0.18/100 -> 0.18 | AA4: =B4*4.18/100 -> 4.18
A5: Arroz, tipo 1, cozido | B5: 100 | C5: =B5*128/100 -> 128 | D5: =B5*2.5/100 -> 2.5 | E5: =B5*0.2/100 -> 0.2 | F5: =B5*0.2/100 -> 0.2 | G5: Tr | H5: Tr | I5: =B5*0.06/100 -> 0.06 | K5: NA | L5: =B5*28.1/100 -> 28.1 | M5: =B5*1.6/100 -> 1.6 | N5: =B5*4/100 -> 4 | O5: =B5*2/100 -> 2 | P5: =B5*0.3/100 -> 0.3 | Q5: =B5*18/100 -> 18 | R5: =B5*0.1/100 -> 0.1 | S5: =B5*1/100 -> 1 | T5: =B5*15/100 -> 15 | U5: =B5*0.02/100 -> 0.02 | V5: =B5*0.5/100 -> 0.5 | W5: NA | X5: Tr | Y5: Tr | Z5: Tr | AA5: Tr
A6: Arroz, tipo 1, cru | B6: 100 | C6: 358 | D6: =B6*7.2/100 -> 7.2 | E6: =B6*0.3/100 -> 0.3 | F6: =B6*0.1/100 -> 0.1 | G6: =B6*0.1/100 -> 0.1 | H6: =B6*0.1/100 -> 0.1 | I6: =B6*0.08/100 -> 0.08 | J6: Tr | K6: NA | L6: =B6*78.8/100 -> 78.8 | M6: =B6*1.6/100 -> 1.6 | N6: =B6*4/100 -> 4 | O6: =B6*30/100 -> 30 | P6: =B6*1.03/100 -> 1.03 | Q6: =B6*104/100 -> 104 | R6: =B6*0.7/100 -> 0.7 | S6: =B6*1/100 -> 1 | T6: =B6*62/100 -> 62 | U6: =B6*0.11/100 -> 0.11 | V6: =B6*1.2/100 -> 1.2 | W6: NA | X6: =B6*0.16/100 -> 0.16 | Y6: Tr | Z6: =B6*0.07/100 -> 0.07 | AA6: =B6*1.12/100 -> 1.12
A7: Arroz, tipo 2, cozido | B7: 100 | C7: =B7*130/100 -> 130 | D7: =B7*2.6/100 -> 2.6 | E7: =B7*0.4/100 -> 0.4 | F7: =B7*0.1/100 -> 0.1 | G7: =B7*0.1/100 -> 0.1 | H7: =B7*0.1/100 -> 0.1 | I7: =B7*0.09/100 -> 0.09 | J7: Tr | K7: NA | L7: =B7*28.2/100 -> 28.2 | M7: =B7*1.1/100 -> 1.1 | N7: =B7*3/100 -> 3 | O7: =B7*6/100 -> 6 | P7: =B7*0.37/100 -> 0.37 | Q7: =B7*22/100 -> 22 | R7: =B7*0.1/100 -> 0.1 | S7: =B7*2/100 -> 2 | T7: =B7*20/100 -> 20 | U7: =B7*0.04/100 -> 0.04 | V7: =B7*0.5/100 -> 0.5 | W7: NA | X7: Tr | Y7: Tr | Z7: Tr | AA7: Tr
A8: Arroz, tipo 2, cru | B8: 100 | C8: =B8*358/100 -> 358 | D8: =B8*7.2/100 -> 7.2 | E8: =B8*0.3/100 -> 0.3 | F8: =B8*0.1/100 -> 0.1 | G8: =B8*0.1/100 -> 0.1 | H8: =B8*0.1/100 -> 0.1 | I8: =B8*0.09/100 -> 0.09 | J8: Tr | K8: NA | L8: =B8*78.9/100 -> 78.9 | M8: =B8*1.7/100 -> 1.7 | N8: =B8*5/100 -> 5 | O8: =B8*29/100 -> 29 | P8: =B8*0.83/100 -> 0.83 | Q8: =B8*82/100 -> 82 | R8: =B8*0.6/100 -> 0.6 | S8: =B8*1/100 -> 1 | T8: =B8*57/100 -> 57 | U8: =B8*0.05/100 -> 0.05 | V8: =B8*1.3/100 -> 1.3 | W8: NA | X8: =B8*0.16/100 -> 0.16 | Y8: Tr | Z8: =B8*0.05/100 -> 0.05 | AA8: =B8*0.92/100 -> 0.92
A9: Aveia, flocos, crua | B9: 100 | C9: =B9*394/100 -> 394 | D9: =B9*13.9/100 -> 13.9 | E9: =B9*8.5/100 -> 8.5 | K9: NA | L9: =B9*66.6/100 -> 66.6 | M9: =B9*9.1/100 -> 9.1 | N9: =B9*48/100 -> 48 | O9: =B9*119/100 -> 119 | Q9: =B9*153/100 -> 153 | R9: =B9*4.4/100 -> 4.4 | S9: =B9*5/100 -> 5 | T9: =B9*336/100 -> 336 | U9: =B9*0.44/100 -> 0.44 | V9: =B9*2.6/100 -> 2.6 | W9: NA | X9: =B9*0.55/100 -> 0.55 | Y9: =B9*0.03/100 -> 0.03 | Z9: Tr | AA9: =B9*4.47/100 -> 4.47
A10: Biscoito, doce, maisena | B10: 100 | C10: =B10*443/100 -> 443 | D10: =B10*8.1/100 -> 8.1 | E10: =B10*12/100 -> 12 | F10: =B10*3.9/100 -> 3.9 | G10: =B10*3.7/100 -> 3.7 | H10: =B10*2.2/100 -> 2.2 | I10: =B10*2.13/100 -> 2.13 | J10: =B10*0.1/100 -> 0.1 | K10: NA | L10: =B10*75.2/100 -> 75.2 | M10: =B10*2.1/100 -> 2.1 | N10: =B10*54/100 -> 54 | O10: =B10*37/100 -> 37 | Q10: =B10*166/100 -> 166 | R10: =B10*1.8/100 -> 1.8 | S10: =B10*352/100 -> 352 | T10: =B10*142/100 -> 142 | U10: =B10*0.17/100 -> 0.17 | V10: =B10*1/100 -> 1 | W10: NA | X10: =B10*1.01/100 -> 1.01 | Y10: =B10*0.42/100 -> 0.42 | AA10: =B10*3.91/100 -> 3.91
A11: Biscoito, doce, recheado com chocolate | B11: 100 | C11: =B11*472/100 -> 472 | D11: =B11*6.4/100 -> 6.4 | E11: =B11*19.6/100 -> 19.6 | F11: =B11*6.2/100 -> 6.2 | G11: =B11*6.6/100 -> 6.6 | H11: =B11*1.7/100 -> 1.7 | I11: =B11*1.68/100 -> 1.68 | J11: =B11*0.06/100 -> 0.06 | K11: Tr | L11: =B11*70.5/100 -> 70.5 | M11: =B11*3/100 -> 3 | N11: =B11*27/100 -> 27 | O11: =B11*48/100 -> 48 | Q11: =B11*139/100 -> 139 | R11: =B11*2.3/100 -> 2.3 | S11: =B11*239/100 -> 239 | T11: =B11*232/100 -> 232 | U11: =B11*0.27/100 -> 0.27 | V11: =B11*1/100 -> 1 | W11: Tr | X11: =B11*0.32/100 -> 0.32 | Y11: =B11*0.39/100 -> 0.39 | Z11: =B11*0.46/100 -> 0.46 | AA11: =B11*2.52/100 -> 2.52
A12: Biscoito, doce, recheado com morango | B12: 100 | C12: =B12*471/100 -> 471 | D12: =B12*5.7/100 -> 5.7 | E12: =B12*19.6/100 -> 19.6 | F12: =B12*6.1/100 -> 6.1 | G12: =B12*6.5/100 -> 6.5 | H12: =B12*1.7/100 -> 1.7 | I12: =B12*1.61/100 -> 1.61 | J12: =B12*0.06/100 -> 0.06 | L12: =B12*71/100 -> 71 | M12: =B12*1.5/100 -> 1.5 | N12: =B12*36/100 -> 36 | O12: =B12*27/100 -> 27 | Q12: =B12*138/100 -> 138 | R12: =B12*1.5/100 -> 1.5 | S12: =B12*230/100 -> 230 | T12: =B12*113/100 -> 113 | U12: =B12*0.13/100 -> 0.13 | V12: =B12*0.7/100 -> 0.7 | W12: Tr | X12: =B12*0.9/100 -> 0.9 | Y12: =B12*0.42/100 -> 0.42 | Z12: =B12*0.21/100 -> 0.21 | AA12: =B12*1.5/100 -> 1.5
A13: Biscoito, doce, wafer, recheado de chocolate | B13: 100 | C13: =B13*502/100 -> 502 | D13: =B13*5.6/100 -> 5.6 | E13: =B13*24.7/100 -> 24.7 | F13: =B13*6.5/100 -> 6.5 | G13: =B13*8.1/100 -> 8.1 | H13: =B13*1.9/100 -> 1.9 | I13: =B13*1.84/100 -> 1.84 | J13: =B13*0.09/100 -> 0.09 | K13: Tr | L13: =B13*67.5/100 -> 67.5 | M13: =B13*1.8/100 -> 1.8 | N13: =B13*23/100 -> 23 | O13: =B13*48/100 -> 48 | Q13: =B13*124/100 -> 124 | R13: =B13*2.4/100 -> 2.4 | S13: =B13*137/100 -> 137 | T13: =B13*240/100 -> 240 | U13: =B13*0.26/100 -> 0.26 | V13: =B13*0.9/100 -> 0.9 | W13: Tr | X13: =B13*0.37/100 -> 0.37 | Y13: =B13*0.03/100 -> 0.03 | Z13: =B13*0.3/100 -> 0.3 | AA13: =B13*1.12/100 -> 1.12
A14: Biscoito, doce, wafer recheado de morango | B14: 100 | C14: =B14*513/100 -> 513 | D14: =B14*4.5/100 -> 4.5 | E14: =B14*26.4/100 -> 26.4 | F14: =B14*6.7/100 -> 6.7 | G14: =B14*8.9/100 -> 8.9 | H14: =B14*1.8/100 -> 1.8 | I14: =B14*1.77/100 -> 1.77 | J14: =B14*0.08/100 -> 0.08 | L14: =B14*67.4/100 -> 67.4 | M14: =B14*0.8/100 -> 0.8 | N14: =B14*14/100 -> 14 | O14: =B14*19/100 -> 19 | Q14: =B14*73/100 -> 73 | R14: =B14*1.1/100 -> 1.1 | S14: =B14*120/100 -> 120 | T14: =B14*75/100 -> 75 | U14: =B14*0.08/100 -> 0.08 | V14: =B14*0.5/100 -> 0.5 | W14: Tr | X14: =B14*0.36/100 -> 0.36 | Y14: Tr | Z14: =B14*0.94/100 -> 0.94 | AA14: =B14*0.37/100 -> 0.37
A15: Biscoito, salgado, cream craker | B15: 100 | C15: =B15*432/100 -> 432 | D15: =B15*10.1/100 -> 10.1 | E15: =B15*14.4/100 -> 14.4 | F15: =B15*4.4/100 -> 4.4 | G15: =B15*4.6/100 -> 4.6 | H15: =B15*2.9/100 -> 2.9 | I15: =B15*2.79/100 -> 2.79 | J15: =B15*0.01/100 -> 0.01 | L15: =B15*68.7/100 -> 68.7 | M15: =B15*2.5/100 -> 2.5 | N15: =B15*20/100 -> 20 | O15: =B15*40/100 -> 40 | Q15: =B15*148/100 -> 148 | R15: =B15*2.2/100 -> 2.2 | S15: =B15*854/100 -> 854 | T15: =B15*181/100 -> 181 | U15: =B15*0.18/100 -> 0.18 | V15: =B15*1.1/100 -> 1.1 | W15: NA | X15: =B15*0.71/100 -> 0.71 | Y15: =B15*0.13/100 -> 0.13 | Z15: =B15*0.17/100 -> 0.17 | AA15: =B15*7.14/100 -> 7.14
A16: Bolo, mistura para | B16: 100 | C16: =B16*419/100 -> 419 | D16: =B16*6.2/100 -> 6.2 | E16: =B16*6.1/100 -> 6.1 | F16: =B16*2.2/100 -> 2.2 | G16: =B16*1.7/100 -> 1.7 | H16: =B16*0.8/100 -> 0.8 | I16: =B16*0.8/100 -> 0.8 | J16: =B16*0.04/100 -> 0.04 | K16: Tr | L16: =B16*84.7/100 -> 84.7 | M16: =B16*1.7/100 -> 1.7 | N16: =B16*59/100 -> 59 | O16: =B16*28/100 -> 28 | Q16: =B16*333/100 -> 333 | R16: =B16*1.2/100 -> 1.2 | S16: =B16*463/100 -> 463 | T16: 0 | U16: =B16*1.15/100 -> 1.15 | V16: =B16*0.6/100 -> 0.6 | W16: NA | X16: =B16*0.18/100 -> 0.18 | Y16: Tr | Z16: =B16*1.5/100 -> 1.5 | AA16: =B16*1.52/100 -> 1.52
A17: Bolo, pronto, aipim | B17: 100 | C17: =B17*324/100 -> 324 | D17: =B17*4.4/100 -> 4.4 | E17: =B17*12.7/100 -> 12.7 | F17: =B17*5/100 -> 5 | G17: =B17*3.9/100 -> 3.9 | H17: =B17*1.1/100 -> 1.1 | I17: =B17*1/100 -> 1 | J17: =B17*0.06/100 -> 0.06 | K17: =B17*73/100 -> 73 | L17: =B17*47.9/100 -> 47.9 | M17: =B17*0.7/100 -> 0.7 | N17: =B17*85/100 -> 85 | O17: =B17*10/100 -> 10 | P17: =B17*0.11/100 -> 0.11 | Q17: =B17*122/100 -> 122 | R17: =B17*0.5/100 -> 0.5 | S17: =B17*111/100 -> 111 | T17: =B17*135/100 -> 135 | U17: =B17*0.05/100 -> 0.05 | V17: =B17*0.4/100 -> 0.4 | W17: Tr | X17: =B17*0.13/100 -> 0.13 | Y17: =B17*0.07/100 -> 0.07 | Z17: Tr | AA17: Tr | AB17: Tr
A18: Bolo, pronto, chocolate | B18: 100 | C18: =B18*410/100 -> 410 | D18: =B18*6.2/100 -> 6.2 | E18: =B18*18.2/100 -> 18.2 | F18: =B18*5.5/100 -> 5.5 | G18: =B18*6.2/100 -> 6.2 | H18: =B18*3/100 -> 3 | I18: =B18*2.83/100 -> 2.83 | J18: =B18*0.04/100 -> 0.04 | K18: =B18*77/100 -> 77 | L18: =B18*54.7/100 -> 54.7 | M18: =B18*1.4/100 -> 1.4 | N18: =B18*75/100 -> 75 | O18: =B18*28/100 -> 28 | P18: =B18*0.38/100 -> 0.38 | Q18: =B18*197/100 -> 197 | R18: =B18*2.1/100 -> 2.1 | S18: =B18*283/100 -> 283 | T18: =B18*212/100 -> 212 | U18: =B18*0.05/100 -> 0.05 | V18: =B18*0.7/100 -> 0.7 | W18: Tr | Y18: =B18*0.09/100 -> 0.09 | Z18: =B18*0.05/100 -> 0.05 | AA18: Tr | AB18: Tr
A19: Bolo, pronto, coco | B19: 100 | C19: =B19*333/100 -> 333 | D19: =B19*5.7/100 -> 5.7 | E19: =B19*11.3/100 -> 11.3 | F19: =B19*4.9/100 -> 4.9 | G19: =B19*3/100 -> 3 | H19: =B19*1.8/100 -> 1.8 | I19: =B19*1.69/100 -> 1.69 | J19: =B19*0.06/100 -> 0.06 | K19: =B19*63/100 -> 63 | L19: =B19*52.3/100 -> 52.3 | M19: =B19*1.1/100 -> 1.1 | N19: =B19*57/100 -> 57 | O19: =B19*16/100 -> 16 | P19: =B19*0.4/100 -> 0.4 | Q19: =B19*303/100 -> 303 | R19: =B19*0.8/100 -> 0.8 | S19: =B19*190/100 -> 190 | T19: =B19*143/100 -> 143 | U19: =B19*0.09/100 -> 0.09 | V19: =B19*0.7/100 -> 0.7 | W19: Tr | X19: =B19*0.15/100 -> 0.15 | Y19: =B19*0.06/100 -> 0.06 | Z19: Tr | AA19: Tr | AB19: Tr
A20: Bolo, pronto, milho | B20: 100 | C20: =B20*311/100 -> 311 | D20: =B20*4.8/100 -> 4.8 | E20: =B20*12.4/100 -> 12.4 | F20: =B20*4.5/100 -> 4.5 | G20: =B20*3.9/100 -> 3.9 | H20: =B20*1.5/100 -> 1.5 | I20: =B20*1.34/100 -> 1.34 | J20: =B20*0.08/100 -> 0.08 | K20: =B20*82/100 -> 82 | L20: =B20*45.1/100 -> 45.1 | M20: =B20*0.7/100 -> 0.7 | N20: =B20*83/100 -> 83 | O20: =B20*10/100 -> 10 | P20: =B20*0.11/100 -> 0.11 | Q20: =B20*128/100 -> 128 | R20: =B20*0.7/100 -> 0.7 | S20: =B20*134/100 -> 134 | T20: =B20*118/100 -> 118 | U20: =B20*0.04/100 -> 0.04 | V20: =B20*0.4/100 -> 0.4 | W20: =B20*57/100 -> 57 | X20: =B20*0.11/100 -> 0.11 | Y20: =B20*0.05/100 -> 0.05 | Z20: Tr | AA20: Tr | AB20: Tr
A21: Canjica, branca, crua | B21: 100 | C21: =B21*358/100 -> 358 | D21: =B21*7.2/100 -> 7.2 | E21: =B21*1/100 -> 1 | F21: =B21*0.3/100 -> 0.3 | G21: =B21*0.2/100 -> 0.2 | H21: =B21*0.4/100 -> 0.4 | I21: =B21*0.38/100 -> 0.38 | J21: =B21*0.01/100 -> 0.01 | K21: NA | L21: =B21*78.1/100 -> 78.1 | M21: =B21*5.5/100 -> 5.5 | N21: =B21*2/100 -> 2 | O21: =B21*12/100 -> 12 | P21: =B21*0.09/100 -> 0.09 | Q21: =B21*48/100 -> 48 | R21: =B21*0.3/100 -> 0.3 | S21: =B21*1/100 -> 1 | T21: =B21*93/100 -> 93 | U21: =B21*0.05/100 -> 0.05 | V21: =B21*0.4/100 -> 0.4 | W21: NA | X21: Tr | Y21: Tr | Z21: Tr | AA21: Tr | AB21: Tr
A22: Cereais, milho, flocos, com sal | B22: 100 | C22: =B22*370/100 -> 370 | D22: =B22*7.3/100 -> 7.3 | E22: =B22*1.6/100 -> 1.6 | F22: =B22*0.5/100 -> 0.5 | G22: =B22*0.6/100 -> 0.6 | H22: =B22*0.9/100 -> 0.9 | I22: =B22*0.89/100 -> 0.89 | J22: =B22*0.03/100 -> 0.03 | K22: NA | L22: =B22*80.8/100 -> 80.8 | M22: =B22*5.3/100 -> 5.3 | N22: =B22*2/100 -> 2 | O22: =B22*20/100 -> 20 | P22: Tr | Q22: =B22*91/100 -> 91 | R22: =B22*0.5/100 -> 0.5 | S22: =B22*272/100 -> 272 | T22: =B22*69/100 -> 69 | U22: Tr | V22: =B22*0.6/100 -> 0.6 | W22: NA | X22: =B22*0.12/100 -> 0.12 | Y22: Tr | Z22: =B22*0.06/100 -> 0.06 | AA22: Tr | AB22: Tr
A23: Cereais, milho, flocos, sem sal | B23: 100 | C23: =B23*363/100 -> 363 | D23: =B23*6.9/100 -> 6.9 | E23: =B23*1.2/100 -> 1.2 | F23: =B23*0.3/100 -> 0.3 | G23: =B23*0.3/100 -> 0.3 | H23: =B23*0.6/100 -> 0.6 | I23: =B23*0.6/100 -> 0.6 | J23: =B23*0.02/100 -> 0.02 | K23: NA | L23: =B23*80.4/100 -> 80.4 | M23: =B23*1.8/100 -> 1.8 | N23: =B23*2/100 -> 2 | O23: =B23*17/100 -> 17 | P23: Tr | Q23: =B23*58/100 -> 58 | R23: =B23*1.7/100 -> 1.7 | S23: =B23*31/100 -> 31 | T23: =B23*29/100 -> 29 | U23: =B23*0.24/100 -> 0.24 | V23: =B23*0.3/100 -> 0.3 | W23: NA | X23: =B23*0.05/100 -> 0.05 | Y23: Tr | Z23: =B23*0.04/100 -> 0.04 | AA23: Tr | AB23: Tr
A24: Cereais, mingau, milho, infantil | B24: 100 | C24: =B24*394/100 -> 394 | D24: =B24*6.4/100 -> 6.4 | E24: =B24*1.1/100 -> 1.1 | F24: =B24*0.3/100 -> 0.3 | G24: =B24*0.3/100 -> 0.3 | H24: =B24*0.5/100 -> 0.5 | I24: =B24*0.45/100 -> 0.45 | J24: =B24*0.01/100 -> 0.01 | K24: NA | L24: =B24*87.3/100 -> 87.3 | M24: =B24*3.2/100 -> 3.2 | N24: =B24*219/100 -> 219 | O24: =B24*16/100 -> 16 | Q24: =B24*169/100 -> 169 | R24: =B24*3/100 -> 3 | S24: =B24*399/100 -> 399 | T24: =B24*82/100 -> 82 | U24: =B24*0.04/100 -> 0.04 | V24: =B24*0.4/100 -> 0.4 | W24: =B24*21/100 -> 21 | X24: =B24*3.72/100 -> 3.72 | Y24: =B24*0.47/100 -> 0.47 | Z24: =B24*5.08/100 -> 5.08 | AA24: =B24*24.16/100 -> 24.16 | AB24: =B24*109.4/100 -> 109.4
A25: Cereais, mistura para vitamina, trigo, cevada e aveia | B25: 100 | C25: =B25*381/100 -> 381 | D25: =B25*8.9/100 -> 8.9 | E25: =B25*2.1/100 -> 2.1 | F25: =B25*0.5/100 -> 0.5 | G25: =B25*0.4/100 -> 0.4 | H25: =B25*1/100 -> 1 | I25: =B25*0.43/100 -> 0.43 | J25: =B25*0.01/100 -> 0.01 | K25: NA | L25: =B25*81.6/100 -> 81.6 | M25: =B25*5/100 -> 5 | N25: =B25*584/100 -> 584 | O25: =B25*72/100 -> 72 | P25: =B25*2.28/100 -> 2.28 | Q25: =B25*515/100 -> 515 | R25: =B25*12.6/100 -> 12.6 | S25: =B25*1163/100 -> 1163 | T25: =B25*244/100 -> 244 | U25: =B25*0.21/100 -> 0.21 | V25: =B25*2/100 -> 2 | W25: Tr | X25: =B25*0.76/100 -> 0.76 | Y25: =B25*0.88/100 -> 0.88 | Z25: =B25*1.49/100 -> 1.49 | AA25: =B25*7.46/100 -> 7.46
A26: Cereal matinal, milho | B26: 100 | C26: =B26*365/100 -> 365 | D26: =B26*7.2/100 -> 7.2 | E26: =B26*1/100 -> 1 | K26: NA | L26: =B26*83.8/100 -> 83.8 | M26: =B26*4.1/100 -> 4.1 | N26: =B26*143/100 -> 143 | O26: =B26*11/100 -> 11 | Q26: =B26*101/100 -> 101 | R26: =B26*3.1/100 -> 3.1 | S26: =B26*655/100 -> 655 | T26: =B26*83/100 -> 83 | U26: =B26*0.06/100 -> 0.06 | V26: =B26*7.6/100 -> 7.6 | W26: NA | X26: =B26*0.76/100 -> 0.76 | Y26: =B26*1.02/100 -> 1.02 | Z26: =B26*2.25/100 -> 2.25 | AA26: =B26*11.04/100 -> 11.04
A27: Cereal matinal, milho, açúcar | B27: 100 | C27: =B27*377/100 -> 377 | D27: =B27*4.7/100 -> 4.7 | E27: =B27*0.7/100 -> 0.7 | K27: NA | L27: =B27*88.8/100 -> 88.8 | M27: =B27*2.1/100 -> 2.1 | N27: =B27*56/100 -> 56 | O27: =B27*8/100 -> 8 | Q27: =B27*43/100 -> 43 | R27: =B27*3.9/100 -> 3.9 | S27: =B27*405/100 -> 405 | T27: =B27*52/100 -> 52 | U27: =B27*0.04/100 -> 0.04 | V27: =B27*8.5/100 -> 8.5 | W27: NA | X27: =B27*0.73/100 -> 0.73 | Y27: =B27*1.11/100 -> 1.11 | Z27: =B27*0.79/100 -> 0.79 | AA27: =B27*10.13/100 -> 10.13
A28: Creme, de arroz, pó | B28: 100 | C28: =B28*386/100 -> 386 | D28: =B28*7/100 -> 7 | E28: =B28*1.2/100 -> 1.2 | F28: =B28*0.4/100 -> 0.4 | G28: =B28*0.3/100 -> 0.3 | H28: =B28*0.4/100 -> 0.4 | I28: =B28*0.43/100 -> 0.43 | J28: =B28*0.01/100 -> 0.01 | K28: NA | L28: =B28*83.9/100 -> 83.9 | M28: =B28*1.1/100 -> 1.1 | N28: =B28*7/100 -> 7 | O28: =B28*51/100 -> 51 | P28: =B28*1.24/100 -> 1.24 | Q28: =B28*153/100 -> 153 | R28: =B28*0.6/100 -> 0.6 | S28: =B28*1/100 -> 1 | T28: =B28*115/100 -> 115 | U28: =B28*0.04/100 -> 0.04 | V28: =B28*1.9/100 -> 1.9 | W28: NA | X28: =B28*0.22/100 -> 0.22 | Y28: Tr | Z28: =B28*0.05/100 -> 0.05 | AA28: Tr | AB28: Tr
A29: Creme, de milho, pó | B29: 100 | C29: =B29*333/100 -> 333 | D29: =B29*4.8/100 -> 4.8 | E29: =B29*1.6/100 -> 1.6 | F29: =B29*0.3/100 -> 0.3 | G29: =B29*0.5/100 -> 0.5 | H29: =B29*0.8/100 -> 0.8 | I29: =B29*0.75/100 -> 0.75 | J29: =B29*0.02/100 -> 0.02 | K29: NA | L29: =B29*86.1/100 -> 86.1 | M29: =B29*3.7/100 -> 3.7 | N29: =B29*323/100 -> 323 | O29: =B29*30/100 -> 30 | P29: =B29*0.2/100 -> 0.2 | Q29: =B29*303/100 -> 303 | R29: =B29*4.3/100 -> 4.3 | S29: =B29*594/100 -> 594 | T29: =B29*166/100 -> 166 | U29: =B29*0.04/100 -> 0.04 | V29: =B29*0.8/100 -> 0.8 | W29: NA | X29: =B29*0.74/100 -> 0.74 | Y29: Tr | Z29: =B29*2.05/100 -> 2.05 | AA29: Tr | AB29: =B29*96.3/100 -> 96.3
A30: Curau, milho verde, pó | B30: 100 | C30: =B30*402/100 -> 402 | D30: =B30*2.2/100 -> 2.2 | E30: =B30*13.4/100 -> 13.4 | F30: =B30*3/100 -> 3 | G30: =B30*4.9/100 -> 4.9 | H30: =B30*1.4/100 -> 1.4 | I30: =B30*1.38/100 -> 1.38 | J30: =B30*0.03/100 -> 0.03 | K30: NA | L30: =B30*79.8/100 -> 79.8 | M30: =B30*2.5/100 -> 2.5 | N30: =B30*31/100 -> 31 | O30: =B30*9/100 -> 9 | P30: =B30*0.05/100 -> 0.05 | Q30: =B30*45/100 -> 45 | R30: =B30*0.9/100 -> 0.9 | S30: =B30*223/100 -> 223 | T30: =B30*55/100 -> 55 | U30: =B30*0.03/100 -> 0.03 | V30: =B30*0.2/100 -> 0.2 | W30: NA | X30: =B30*0.13/100 -> 0.13 | Y30: Tr | Z30: Tr | AA30: Tr | AB30: Tr
A31: Farinha, de arroz, enrriquecida | B31: 100 | C31: =B31*363/100 -> 363 | D31: =B31*1.3/100 -> 1.3 | E31: =B31*0.3/100 -> 0.3 | F31: =B31*0.2/100 -> 0.2 | G31: =B31*0.1/100 -> 0.1 | H31: =B31*0.2/100 -> 0.2 | I31: =B31*0.17/100 -> 0.17 | J31: =B31*0.01/100 -> 0.01 | K31: NA | L31: =B31*85.5/100 -> 85.5 | M31: =B31*0.6/100 -> 0.6 | N31: =B31*1/100 -> 1 | O31: =B31*4/100 -> 4 | P31: =B31*0.04/100 -> 0.04 | Q31: =B31*36/100 -> 36 | R31: =B31*31.4/100 -> 31.4 | S31: =B31*17/100 -> 17 | T31: =B31*13/100 -> 13 | U31: Tr | V31: =B31*8.5/100 -> 8.5 | W31: NA | X31: =B31*3.23/100 -> 3.23 | Y31: Tr | Z31: =B31*3.47/100 -> 3.47 | AA31: =B31*24.42/100 -> 24.42 | AB31: =B31*173.6/100 -> 173.6
A32: Farinha, de centeio, integral | B32: 100 | C32: =B32*336/100 -> 336 | D32: =B32*12.5/100 -> 12.5 | E32: =B32*1.8/100 -> 1.8 | F32: =B32*0.3/100 -> 0.3 | G32: =B32*0.3/100 -> 0.3 | H32: =B32*0.8/100 -> 0.8 | I32: =B32*0.73/100 -> 0.73 | J32: =B32*0.06/100 -> 0.06 | K32: NA | L32: =B32*73.3/100 -> 73.3 | M32: =B32*15.5/100 -> 15.5 | N32: =B32*34/100 -> 34 | O32: =B32*120/100 -> 120 | P32: =B32*3.86/100 -> 3.86 | Q32: =B32*340/100 -> 340 | R32: =B32*4.7/100 -> 4.7 | S32: =B32*41/100 -> 41 | T32: =B32*334/100 -> 334 | U32: =B32*0.56/100 -> 0.56 | V32: =B32*2.7/100 -> 2.7 | W32: NA | X32: =B32*0.29/100 -> 0.29 | Y32: =B32*0.03/100 -> 0.03 | Z32: =B32*0.08/100 -> 0.08 | AA32: Tr | AB32: Tr
A33: Farinha, de milho, amarela | B33: 100 | C33: =B33*351/100 -> 351 | D33: =B33*7.2/100 -> 7.2 | E33: =B33*1.5/100 -> 1.5 | F33: =B33*0.4/100 -> 0.4 | G33: =B33*0.4/100 -> 0.4 | H33: =B33*0.6/100 -> 0.6 | I33: =B33*0.63/100 -> 0.63 | J33: =B33*0.02/100 -> 0.02 | K33: NA | L33: =B33*79.1/100 -> 79.1 | M33: =B33*5.5/100 -> 5.5 | N33: =B33*1/100 -> 1 | O33: =B33*31/100 -> 31 | P33: Tr | Q33: =B33*84/100 -> 84 | R33: =B33*2.3/100 -> 2.3 | S33: =B33*45/100 -> 45 | T33: =B33*58/100 -> 58 | U33: =B33*0.27/100 -> 0.27 | V33: =B33*0.6/100 -> 0.6 | W33: NA | X33: =B33*0.25/100 -> 0.25 | Y33: Tr | Z33: =B33*0.25/100 -> 0.25 | AA33: Tr | AB33: Tr
A34: Farinha, de rosca | B34: 100 | C34: =B34*371/100 -> 371 | D34: =B34*11.4/100 -> 11.4 | E34: =B34*1.5/100 -> 1.5 | F34: =B34*0.6/100 -> 0.6 | G34: =B34*0.4/100 -> 0.4 | H34: =B34*0.8/100 -> 0.8 | I34: =B34*0.74/100 -> 0.74 | J34: =B34*0.05/100 -> 0.05 | K34: NA | L34: =B34*75.8/100 -> 75.8 | M34: =B34*4.8/100 -> 4.8 | N34: =B34*35/100 -> 35 | O34: =B34*57/100 -> 57 | P34: =B34*1.62/100 -> 1.62 | Q34: =B34*195/100 -> 195 | R34: =B34*6.7/100 -> 6.7 | S34: =B34*333/100 -> 333 | T34: =B34*212/100 -> 212 | U34: =B34*0.26/100 -> 0.26 | V34: =B34*1.7/100 -> 1.7 | W34: NA | X34: =B34*0.25/100 -> 0.25 | Y34: Tr | Z34: =B34*0.09/100 -> 0.09 | AA34: Tr | AB34: Tr
A35: Farinha, de trigo | B35: 100 | C35: =B35*360/100 -> 360 | D35: =B35*9.8/100 -> 9.8 | E35: =B35*1.4/100 -> 1.4 | K35: NA | L35: =B35*75.1/100 -> 75.1 | M35: =B35*2.3/100 -> 2.3 | N35: =B35*18/100 -> 18 | O35: =B35*31/100 -> 31 | Q35: =B35*115/100 -> 115 | R35: =B35*1/100 -> 1 | S35: =B35*1/100 -> 1 | T35: =B35*151/100 -> 151 | U35: =B35*0.15/100 -> 0.15 | V35: =B35*0.8/100 -> 0.8 | W35: NA | X35: =B35*0.31/100 -> 0.31 | Y35: Tr | AA35: =B35*0.89/100 -> 0.89
A36: Farinha, láctea, de cereais | B36: 100 | C36: =B36*415/100 -> 415 | D36: =B36*11.9/100 -> 11.9 | E36: =B36*5.8/100 -> 5.8 | F36: =B36*3.3/100 -> 3.3 | G36: =B36*1.4/100 -> 1.4 | H36: =B36*0.6/100 -> 0.6 | I36: =B36*0.59/100 -> 0.59 | J36: =B36*0.03/100 -> 0.03 | K36: =B36*11/100 -> 11 | L36: =B36*77.8/100 -> 77.8 | M36: =B36*1.9/100 -> 1.9 | N36: =B36*196/100 -> 196 | O36: =B36*58/100 -> 58 | Q36: =B36*296/100 -> 296 | R36: =B36*8.7/100 -> 8.7 | S36: =B36*125/100 -> 125 | T36: =B36*366/100 -> 366 | U36: =B36*0.19/100 -> 0.19 | V36: =B36*1.7/100 -> 1.7 | W36: =B36*492/100 -> 492 | X36: =B36*1.43/100 -> 1.43 | Y36: =B36*1.13/100 -> 1.13 | Z36: =B36*1.14/100 -> 1.14 | AA36: =B36*9.5/100 -> 9.5
A37: Lasanha, massa fresca, cozida | B37: 100 | C37: =B37*164/100 -> 164 | D37: =B37*5.8/100 -> 5.8 | E37: =B37*1.2/100 -> 1.2 | F37: =B37*0.6/100 -> 0.6 | G37: =B37*0.4/100 -> 0.4 | H37: =B37*0.1/100 -> 0.1 | I37: =B37*0.1/100 -> 0.1 | K37: NA | L37: =B37*32.5/100 -> 32.5 | M37: =B37*1.6/100 -> 1.6 | N37: =B37*10/100 -> 10 | O37: =B37*4/100 -> 4 | P37: =B37*0.2/100 -> 0.2 | Q37: =B37*42/100 -> 42 | R37: =B37*1.2/100 -> 1.2 | S37: =B37*207/100 -> 207 | T37: =B37*54/100 -> 54 | U37: =B37*0.07/100 -> 0.07 | V37: =B37*0.4/100 -> 0.4 | W37: NA | X37: =B37*0.04/100 -> 0.04 | Y37: Tr | Z37: Tr | AA37: =B37*3.96/100 -> 3.96
A38: Lasanha, massa fresca, crua | B38: 100 | C38: =B38*220/100 -> 220 | D38: =B38*7/100 -> 7 | E38: =B38*1.3/100 -> 1.3 | F38: =B38*0.5/100 -> 0.5 | G38: =B38*0.4/100 -> 0.4 | H38: =B38*0.4/100 -> 0.4 | I38: =B38*0.38/100 -> 0.38 | J38: =B38*0.01/100 -> 0.01 | K38: NA | L38: =B38*45.1/100 -> 45.1 | M38: =B38*1.6/100 -> 1.6 | N38: =B38*17/100 -> 17 | O38: =B38*13/100 -> 13 | P38: =B38*0.34/100 -> 0.34 | Q38: =B38*82/100 -> 82 | R38: =B38*1.9/100 -> 1.9 | S38: =B38*667/100 -> 667 | T38: =B38*137/100 -> 137 | U38: =B38*0.1/100 -> 0.1 | V38: =B38*0.8/100 -> 0.8 | W38: NA | X38: =B38*0.08/100 -> 0.08 | Y38: Tr | Z38: Tr | AA38: Tr
A39: Macarrão, instantâneo | B39: 100 | C39: =B39*436/100 -> 436 | D39: =B39*8.8/100 -> 8.8 | E39: =B39*17.2/100 -> 17.2 | K39: NA | L39: =B39*62.4/100 -> 62.4 | M39: =B39*5.6/100 -> 5.6 | N39: =B39*18/100 -> 18 | O39: =B39*19/100 -> 19 | Q39: =B39*112/100 -> 112 | R39: =B39*0.8/100 -> 0.8 | S39: =B39*1516/100 -> 1516 | T39: =B39*148/100 -> 148 | U39: =B39*0.1/100 -> 0.1 | V39: =B39*0.5/100 -> 0.5 | W39: NA | X39: =B39*1.18/100 -> 1.18 | Y39: =B39*0.04/100 -> 0.04 | Z39: =B39*0.53/100 -> 0.53 | AA39: =B39*9.37/100 -> 9.37
A40: Macarrão, trigo, cru | B40: 100 | C40: =B40*371/100 -> 371 | D40: =B40*10/100 -> 10 | E40: =B40*1.3/100 -> 1.3 | K40: NA | L40: =B40*77.9/100 -> 77.9 | M40: =B40*2.9/100 -> 2.9 | N40: =B40*17/100 -> 17 | O40: =B40*28/100 -> 28 | Q40: =B40*100/100 -> 100 | R40: =B40*0.9/100 -> 0.9 | S40: =B40*7/100 -> 7 | T40: =B40*147/100 -> 147 | U40: =B40*0.15/100 -> 0.15 | V40: =B40*0.8/100 -> 0.8 | W40: NA | X40: =B40*0.18/100 -> 0.18 | Y40: =B40*0.02/100 -> 0.02 | Z40: Tr | AA40: =B40*3.57/100 -> 3.57
...

Sheet TACO v.4  - 2011
A1: Descrição do alimento | B1: Quantidade (g) | C1: Energia (kcal) | D1: Proteína (g) | E1: Lipídeos (g) | F1: Saturada (g) | G1: Monoinsat (g) | H1: Polinsat (g) | I1: ômega 6 | J1: ômega 3 | K1: Colesterol (mg) | L1: CHO (g) | M1: Fibras (g) | N1: Cálcio (mg) | O1: Mg (mg) | P1: Mn (mg) | Q1: P (mg) | R1: Ferro (mg) | S1: Sódio (mg) | T1: Potássio (mg) | U1: Cobre (mg) | V1: Zinco (mg) | W1: Retinol (mcg) | X1: Tiamina (mg) | Y1: Riboflavina (mg) | Z1: Piridoxina (mg) | AA1: Niacina (mg) | AB1: Vit. C (mg)
A2: Cereais e derivados
A3: Arroz, integral, cozido | B3: 100 | C3: =B3*123.5348925/100 -> 123.53489 | D3: =B3*2.58825/100 -> 2.58825 | E3: =B3*1.00033333333333/100 -> 1.0003333 | F3: =B3*0.3/100 -> 0.3 | G3: =B3*0.4/100 -> 0.4 | H3: =B3*0.3/100 -> 0.3 | I3: =B3*0.31/100 -> 0.31 | J3: =B3*0.01/100 -> 0.01 | K3: NA | L3: =B3*25.80975/100 -> 25.80975 | M3: =B3*2.74933333333333/100 -> 2.7493333 | N3: =B3*5.204/100 -> 5.204 | O3: =B3*58.702/100 -> 58.702 | P3: =B3*0.627333333333333/100 -> 0.62733333 | Q3: =B3*105.853/100 -> 105.853 | R3: =B3*0.262/100 -> 0.262 | S3: =B3*1.24466666666667/100 -> 1.2446667 | T3: =B3*75.1516666666667/100 -> 75.151667 | U3: =B3*0.0203333333333333/100 -> 0.020333333 | V3: =B3*0.682666666666667/100 -> 0.68266667 | W3: NA | X3: =B3*0.08/100 -> 0.08 | Y3: Tr | Z3: =B3*0.08/100 -> 0.08 | AA3: Tr
A4: Arroz, integral, cru | B4: 100 | C4: =B4*359.678002032609/100 -> 359.678 | D4: =B4*7.32328586956522/100 -> 7.3232859 | E4: =B4*1.86483333333333/100 -> 1.8648333 | F4: =B4*0.3/100 -> 0.3 | G4: =B4*0.5/100 -> 0.5 | H4: =B4*0.4/100 -> 0.4 | I4: =B4*0.38/100 -> 0.38 | J4: =B4*0.02/100 -> 0.02 | K4: NA | L4: =B4*77.4507141304348/100 -> 77.450714 | M4: =B4*4.81916666666667/100 -> 4.8191667 | N4: =B4*7.818/100 -> 7.818 | O4: =B4*109.71/100 -> 109.71 | P4: =B4*2.99333333333333/100 -> 2.9933333 | Q4: =B4*250.865/100 -> 250.865 | R4: =B4*0.948333333333333/100 -> 0.94833333 | S4: =B4*1.64566666666667/100 -> 1.6456667 | T4: =B4*173.34/100 -> 173.34 | U4: =B4*0.0748333333333333/100 -> 0.074833333 | V4: =B4*1.39516666666667/100 -> 1.3951667 | W4: NA | X4: =B4*0.261666666666667/100 -> 0.26166667 | Y4: Tr | Z4: =B4*0.175/100 -> 0.175 | AA4: =B4*4.18333333333333/100 -> 4.1833333
A5: Arroz, tipo 1, cozido | B5: 100 | C5: =B5*128.258485666667/100 -> 128.25849 | D5: =B5*2.52081666666667/100 -> 2.5208167 | E5: =B5*0.227/100 -> 0.227 | F5: =B5*0.2/100 -> 0.2 | G5: Tr | H5: Tr | I5: =B5*0.06/100 -> 0.06 | K5: NA | L5: =B5*28.05985/100 -> 28.05985 | M5: =B5*1.561/100 -> 1.561 | N5: =B5*3.54433333333333/100 -> 3.5443333 | O5: =B5*2.25333333333333/100 -> 2.2533333 | P5: =B5*0.296666666666667/100 -> 0.29666667 | Q5: =B5*17.945/100 -> 17.945 | R5: =B5*0.0766666666666667/100 -> 0.076666667 | S5: =B5*1.20066666666667/100 -> 1.2006667 | T5: =B5*14.6736666666667/100 -> 14.673667 | U5: =B5*0.015/100 -> 0.015 | V5: =B5*0.491333333333333/100 -> 0.49133333 | W5: NA | X5: Tr | Y5: Tr | Z5: Tr | AA5: Tr
A6: Arroz, tipo 1, cru | B6: 100 | C6: =B6*357.789273115942/100 -> 357.78927 | D6: =B6*7.15853985507246/100 -> 7.1585399 | E6: =B6*0.335/100 -> 0.335 | F6: =B6*0.1/100 -> 0.1 | G6: =B6*0.1/100 -> 0.1 | H6: =B6*0.1/100 -> 0.1 | I6: =B6*0.08/100 -> 0.08 | J6: Tr | K6: NA | L6: =B6*78.7595434782609/100 -> 78.759543 | M6: =B6*1.63916666666667/100 -> 1.6391667 | N6: =B6*4.41433333333333/100 -> 4.4143333 | O6: =B6*30.3836666666667/100 -> 30.383667 | P6: =B6*1.03233333333333/100 -> 1.0323333 | Q6: =B6*104.207583333333/100 -> 104.20758 | R6: =B6*0.6777475/100 -> 0.6777475 | S6: =B6*1.01916666666667/100 -> 1.0191667 | T6: =B6*62.4994166666667/100 -> 62.499417 | U6: =B6*0.114833333333333/100 -> 0.11483333 | V6: =B6*1.22483333333333/100 -> 1.2248333 | W6: NA | X6: =B6*0.163333333333333/100 -> 0.16333333 | Y6: Tr | Z6: =B6*0.0691666666666667/100 -> 0.069166667 | AA6: =B6*1.11666666666667/100 -> 1.1166667
A7: Arroz, tipo 2, cozido | B7: 100 | C7: =B7*130.119648333333/100 -> 130.11965 | D7: =B7*2.56841666666667/100 -> 2.5684167 | E7: =B7*0.361666666666667/100 -> 0.36166667 | F7: =B7*0.1/100 -> 0.1 | G7: =B7*0.1/100 -> 0.1 | H7: =B7*0.1/100 -> 0.1 | I7: =B7*0.09/100 -> 0.09 | J7: Tr | K7: NA | L7: =B7*28.1925833333333/100 -> 28.192583 | M7: =B7*1.06966666666667/100 -> 1.0696667 | N7: =B7*3.33366666666667/100 -> 3.3336667 | O7: =B7*6.05333333333333/100 -> 6.0533333 | P7: =B7*0.371/100 -> 0.371 | Q7: =B7*21.5213333333333/100 -> 21.521333 | R7: =B7*0.0503333333333333/100 -> 0.050333333 | S7: =B7*1.95966666666667/100 -> 1.9596667 | T7: =B7*20.2033333333333/100 -> 20.203333 | U7: =B7*0.041/100 -> 0.041 | V7: =B7*0.549333333333333/100 -> 0.54933333 | W7: NA | X7: Tr | Y7: Tr | Z7: Tr | AA7: Tr
A8: Arroz, tipo 2, cru | B8: 100 | C8: =B8*358.116761456522/100 -> 358.11676 | D8: =B8*7.24188297101449/100 -> 7.241883 | E8: =B8*0.2755/100 -> 0.2755 | F8: =B8*0.1/100 -> 0.1 | G8: =B8*0.1/100 -> 0.1 | H8: =B8*0.1/100 -> 0.1 | I8: =B8*0.09/100 -> 0.09 | J8: Tr | K8: NA | L8: =B8*78.8814503623188/100 -> 78.88145 | M8: =B8*1.71983333333333/100 -> 1.7198333 | N8: =B8*4.8335/100 -> 4.8335 | O8: =B8*29.2390833333333/100 -> 29.239083 | P8: =B8*0.828/100 -> 0.828 | Q8: =B8*82.0439166666667/100 -> 82.043917 | R8: =B8*0.597833333333333/100 -> 0.59783333 | S8: =B8*0.568833333333333/100 -> 0.56883333 | T8: =B8*57.2845833333333/100 -> 57.284583 | U8: =B8*0.052/100 -> 0.052 | V8: =B8*1.27208333333333/100 -> 1.2720833 | W8: NA | X8: =B8*0.163333333333333/100 -> 0.16333333 | Y8: Tr | Z8: =B8*0.0491666666666667/100 -> 0.049166667 | AA8: =B8*0.918333333333333/100 -> 0.91833333
A9: Aveia, flocos, crua | B9: 100 | C9: =B9*393.822689449275/100 -> 393.82269 | D9: =B9*13.9210260869565/100 -> 13.921026 | E9: =B9*8.49666666666667/100 -> 8.4966667 | F9: =B9*1.54/100 -> 1.54 | G9: =B9*3.15566666666667/100 -> 3.1556667 | H9: =B9*3.01633333333333/100 -> 3.0163333 | I9: =B9*2.95433333333333/100 -> 2.9543333 | J9: =B9*0.062/100 -> 0.062 | K9: NA | L9: =B9*66.6356405797102/100 -> 66.635641 | M9: =B9*9.13/100 -> 9.13 | N9: =B9*47.89/100 -> 47.89 | O9: =B9*118.762333333333/100 -> 118.76233 | P9: =B9*1.89466666666667/100 -> 1.8946667 | Q9: =B9*153.396666666667/100 -> 153.39667 | R9: =B9*4.44666666666667/100 -> 4.4466667 | S9: =B9*4.62666666666667/100 -> 4.6266667 | T9: =B9*336.333333333333/100 -> 336.33333 | U9: =B9*0.44/100 -> 0.44 | V9: =B9*2.63/100 -> 2.63 | W9: NA | X9: =B9*0.553333333333333/100 -> 0.55333333 | Y9: =B9*0.03/100 -> 0.03 | Z9: Tr | AA9: =B9*4.47/100 -> 4.47 | AB9: =B9*1.35/100 -> 1.35
A10: Biscoito, doce, maisena | B10: 100 | C10: =B10*442.819390144928/100 -> 442.81939 | D10: =B10*8.07252173913043/100 -> 8.0725217 | E10: =B10*11.9666666666667/100 -> 11.966667 | F10: =B10*3.9/100 -> 3.9 | G10: =B10*3.7/100 -> 3.7 | H10: =B10*2.2/100 -> 2.2 | I10: =B10*2.13/100 -> 2.13 | J10: =B10*0.1/100 -> 0.1 | K10: NA | L10: =B10*75.2341449275362/100 -> 75.234145 | M10: =B10*2.1/100 -> 2.1 | N10: =B10*54.45/100 -> 54.45 | O10: =B10*37.1433333333333/100 -> 37.143333 | P10: =B10*0.778333333333333/100 -> 0.77833333 | Q10: =B10*166.103333333333/100 -> 166.10333 | R10: =B10*1.76/100 -> 1.76 | S10: =B10*352.026666666667/100 -> 352.02667 | T10: =B10*141.64/100 -> 141.64 | U10: =B10*0.17/100 -> 0.17 | V10: =B10*1.03/100 -> 1.03 | W10: NA | X10: =B10*1.01/100 -> 1.01 | Y10: =B10*0.416666666666667/100 -> 0.41666667 | Z10: =B10*0.23/100 -> 0.23 | AA10: =B10*3.90666666666667/100 -> 3.9066667 | AB10: =B10*6.21666666666667/100 -> 6.2166667
A11: Biscoito, doce, recheado com chocolate | B11: 100 | C11: =B11*471.824779710145/100 -> 471.82478 | D11: =B11*6.39721739130435/100 -> 6.3972174 | E11: =B11*19.5833333333333/100 -> 19.583333 | F11: =B11*6.2/100 -> 6.2 | G11: =B11*6.6/100 -> 6.6 | H11: =B11*1.7/100 -> 1.7 | I11: =B11*1.68/100 -> 1.68 | J11: =B11*0.06/100 -> 0.06 | K11: Tr | L11: =B11*70.5494492753623/100 -> 70.549449 | M11: =B11*2.95666666666667/100 -> 2.9566667 | N11: =B11*27.23/100 -> 27.23 | O11: =B11*47.9766666666667/100 -> 47.976667 | P11: =B11*0.588/100 -> 0.588 | Q11: =B11*139.45/100 -> 139.45 | R11: =B11*2.27/100 -> 2.27 | S11: =B11*239.2/100 -> 239.2 | T11: =B11*232.4/100 -> 232.4 | U11: =B11*0.273333333333333/100 -> 0.27333333 | V11: =B11*0.993333333333333/100 -> 0.99333333 | W11: Tr | X11: =B11*0.316666666666667/100 -> 0.31666667 | Y11: =B11*0.393333333333333/100 -> 0.39333333 | Z11: =B11*0.456666666666667/100 -> 0.45666667 | AA11: =B11*2.52333333333333/100 -> 2.5233333 | AB11: =B11*3.52666666666667/100 -> 3.5266667
A12: Biscoito, doce, recheado com morango | B12: 100 | C12: =B12*471.174736231884/100 -> 471.17474 | D12: =B12*5.71982608695652/100 -> 5.7198261 | E12: =B12*19.5733333333333/100 -> 19.573333 | F12: =B12*6.1/100 -> 6.1 | G12: =B12*6.5/100 -> 6.5 | H12: =B12*1.7/100 -> 1.7 | I12: =B12*1.61/100 -> 1.61 | J12: =B12*0.06/100 -> 0.06 | K12: Tr | L12: =B12*71.0135072463768/100 -> 71.013507 | M12: =B12*1.53333333333333/100 -> 1.5333333 | N12: =B12*35.78/100 -> 35.78 | O12: =B12*27.1/100 -> 27.1 | P12: =B12*(0.663+0.666+0.648)/3/100 -> 0.659 | Q12: =B12*137.743333333333/100 -> 137.74333 | R12: =B12*1.48/100 -> 1.48 | S12: =B12*229.816666666667/100 -> 229.81667 | T12: =B12*113.013333333333/100 -> 113.01333 | U12: =B12*0.126666666666667/100 -> 0.12666667 | V12: =B12*0.726666666666667/100 -> 0.72666667 | W12: Tr | X12: =B12*0.896666666666667/100 -> 0.89666667 | Y12: =B12*0.42/100 -> 0.42 | Z12: =B12*0.21/100 -> 0.21 | AA12: =B12*1.49666666666667/100 -> 1.4966667 | AB12: Tr
A13: Biscoito, doce, wafer, recheado de chocolate | B13: 100 | C13: =B13*502.456857971014/100 -> 502.45686 | D13: =B13*5.56452173913044/100 -> 5.5645217 | E13: =B13*24.6733333333333/100 -> 24.673333 | F13: =B13*6.5/100 -> 6.5 | G13: =B13*8.1/100 -> 8.1 | H13: =B13*1.9/100 -> 1.9 | I13: =B13*1.84/100 -> 1.84 | J13: =B13*0.09/100 -> 0.09 | K13: Tr | L13: =B13*67.5354782608696/100 -> 67.535478 | M13: =B13*1.80333333333333/100 -> 1.8033333 | N13: =B13*23.3433333333333/100 -> 23.343333 | O13: =B13*47.8533333333333/100 -> 47.853333 | P13: =B13*0.435/100 -> 0.435 | Q13: =B13*124.203333333333/100 -> 124.20333 | R13: =B13*2.44333333333333/100 -> 2.4433333 | S13: =B13*137.24/100 -> 137.24 | T13: =B13*240.453333333333/100 -> 240.45333 | U13: =B13*0.263333333333333/100 -> 0.26333333 | V13: =B13*0.873333333333333/100 -> 0.87333333 | W13: Tr | X13: =B13*0.366666666666667/100 -> 0.36666667 | Y13: =B13*0.03/100 -> 0.03 | Z13: =B13*0.296666666666667/100 -> 0.29666667 | AA13: =B13*1.12/100 -> 1.12 | AB13: Tr
A14: Biscoito, doce, wafer, recheado de morango | B14: 100 | C14: =B14*513.446182608696/100 -> 513.44618 | D14: =B14*4.51704347826087/100 -> 4.5170435 | E14: =B14*26.4/100 -> 26.4 | F14: =B14*6.7/100 -> 6.7 | G14: =B14*8.9/100 -> 8.9 | H14: =B14*1.8/100 -> 1.8 | I14: =B14*1.77/100 -> 1.77 | J14: =B14*0.08/100 -> 0.08 | K14: =B14*1.26733333333333/100 -> 1.2673333 | L14: =B14*67.3529565217391/100 -> 67.352957 | M14: =B14*0.82/100 -> 0.82 | N14: =B14*13.7066666666667/100 -> 13.706667 | O14: =B14*18.54/100 -> 18.54 | P14: =B14*0.279666666666667/100 -> 0.27966667 | Q14: =B14*73.1633333333333/100 -> 73.163333 | R14: =B14*1.09333333333333/100 -> 1.0933333 | S14: =B14*119.9/100 -> 119.9 | T14: =B14*74.8433333333333/100 -> 74.843333 | U14: =B14*0.0833333333333333/100 -> 0.083333333 | V14: =B14*0.513333333333333/100 -> 0.51333333 | W14: Tr | X14: =B14*0.356666666666667/100 -> 0.35666667 | Y14: Tr | Z14: =B14*0.94/100 -> 0.94 | AA14: =B14*0.373333333333333/100 -> 0.37333333
A15: Biscoito, salgado, cream cracker | B15: 100 | C15: =B15*431.73228115942/100 -> 431.73228 | D15: =B15*10.0551304347826/100 -> 10.05513 | E15: =B15*14.4366666666667/100 -> 14.436667 | F15: =B15*4.4/100 -> 4.4 | G15: =B15*4.6/100 -> 4.6 | H15: =B15*2.9/100 -> 2.9 | I15: =B15*2.79/100 -> 2.79 | J15: =B15*0.01/100 -> 0.01 | K15: NA | L15: =B15*68.731536231884/100 -> 68.731536 | M15: =B15*2.51/100 -> 2.51 | N15: =B15*20.0033333333333/100 -> 20.003333 | O15: =B15*39.7466666666667/100 -> 39.746667 | P15: =B15*0.689666666666667/100 -> 0.68966667 | Q15: =B15*148.26/100 -> 148.26 | R15: =B15*2.2/100 -> 2.2 | S15: =B15*854.356666666667/100 -> 854.35667 | T15: =B15*180.613333333333/100 -> 180.61333 | U15: =B15*0.18/100 -> 0.18 | V15: =B15*1.13666666666667/100 -> 1.1366667 | W15: NA | X15: =B15*0.71/100 -> 0.71 | Y15: =B15*0.13/100 -> 0.13 | Z15: =B15*0.17/100 -> 0.17 | AA15: =B15*7.13666666666667/100 -> 7.1366667
A16: Bolo, mistura para | B16: 100 | C16: =B16*418.633333333333/100 -> 418.63333 | D16: =B16*6.15942028985507/100 -> 6.1594203 | E16: =B16*6.12666666666667/100 -> 6.1266667 | F16: =B16*2.095/100 -> 2.095 | G16: =B16*1.89016666666667/100 -> 1.8901667 | H16: =B16*0.813/100 -> 0.813 | I16: =B16*0.778166666666667/100 -> 0.77816667 | J16: =B16*0.0348333333333333/100 -> 0.034833333 | K16: Tr | L16: =B16*84.7139130434783/100 -> 84.713913 | M16: =B16*1.70333333333333/100 -> 1.7033333 | N16: =B16*58.879/100 -> 58.879 | O16: =B16*27.922/100 -> 27.922 | P16: =B16*0.462666666666667/100 -> 0.46266667 | Q16: =B16*332.657666666667/100 -> 332.65767 | R16: =B16*1.21066666666667/100 -> 1.2106667 | S16: =B16*462.88/100 -> 462.88 | T16: =B16*75.363/100 -> 75.363 | U16: =B16*0.153333333333333/100 -> 0.15333333 | V16: =B16*0.582666666666667/100 -> 0.58266667 | W16: NA | X16: =B16*0.176666666666667/100 -> 0.17666667 | Y16: Tr | Z16: =B16*1.50333333333333/100 -> 1.5033333 | AA16: =B16*1.51666666666667/100 -> 1.5166667 | AB16: Tr
A17: Bolo, pronto, aipim | B17: 100 | C17: =B17*323.851666666667/100 -> 323.85167 | D17: =B17*4.41666666666667/100 -> 4.4166667 | E17: =B17*12.7476666666667/100 -> 12.747667 | F17: =B17*5/100 -> 5 | G17: =B17*3.9/100 -> 3.9 | H17: =B17*1.1/100 -> 1.1 | I17: =B17*1.04/100 -> 1.04 | J17: =B17*0.06/100 -> 0.06 | K17: =B17*73.204/100 -> 73.204 | L17: =B17*47.864/100 -> 47.864 | M17: =B17*0.690666666666667/100 -> 0.69066667 | N17: =B17*85.0223333333333/100 -> 85.022333 | O17: =B17*10.344/100 -> 10.344 | P17: =B17*0.107/100 -> 0.107 | Q17: =B17*122.194/100 -> 122.194 | R17: =B17*0.489/100 -> 0.489 | S17: =B17*111.008333333333/100 -> 111.00833 | T17: =B17*134.822666666667/100 -> 134.82267 | U17: =B17*0.0516666666666667/100 -> 0.051666667 | V17: =B17*0.415666666666667/100 -> 0.41566667 | W17: Tr | X17: =B17*0.13/100 -> 0.13 | Y17: =B17*0.07/100 -> 0.07 | Z17: Tr | AA17: Tr | AB17: Tr
A18: Bolo, pronto, chocolate | B18: 100 | C18: =B18*410.013666666667/100 -> 410.01367 | D18: =B18*6.22291666666667/100 -> 6.2229167 | E18: =B18*18.4723333333333/100 -> 18.472333 | F18: =B18*5.5/100 -> 5.5 | G18: =B18*6.2/100 -> 6.2 | H18: =B18*3/100 -> 3 | I18: =B18*2.85/100 -> 2.85 | J18: =B18*0.04/100 -> 0.04 | K18: =B18*76.7976666666667/100 -> 76.797667 | L18: =B18*54.71775/100 -> 54.71775 | M18: =B18*1.43/100 -> 1.43 | N18: =B18*74.5846666666667/100 -> 74.584667 | O18: =B18*27.6866666666667/100 -> 27.686667 | P18: =B18*0.379333333333333/100 -> 0.37933333 | Q18: =B18*196.976666666667/100 -> 196.97667 | R18: =B18*2.13233333333333/100 -> 2.1323333 | S18: =B18*283.3/100 -> 283.3 | T18: =B18*211.763333333333/100 -> 211.76333 | U18: =B18*0.0463333333333333/100 -> 0.046333333 | V18: =B18*0.713666666666667/100 -> 0.71366667 | W18: Tr | X18: =B18*0.133333333333333/100 -> 0.13333333 | Y18: =B18*0.0933333333333333/100 -> 0.093333333 | Z18: =B18*0.05/100 -> 0.05 | AA18: Tr | AB18: Tr
A19: Bolo, pronto, coco | B19: 100 | C19: =B19*333.437666666667/100 -> 333.43767 | D19: =B19*5.66666666666667/100 -> 5.6666667 | E19: =B19*11.2963333333333/100 -> 11.296333 | F19: =B19*4.9/100 -> 4.9 | G19: =B19*3/100 -> 3 | H19: =B19*1.8/100 -> 1.8 | I19: =B19*1.71/100 -> 1.71 | J19: =B19*0.06/100 -> 0.06 | K19: =B19*63.2076666666667/100 -> 63.207667 | L19: =B19*52.276/100 -> 52.276 | M19: =B19*1.055/100 -> 1.055 | N19: =B19*57.1053333333333/100 -> 57.105333 | O19: =B19*16.2516666666667/100 -> 16.251667 | P19: =B19*0.399/100 -> 0.399 | Q19: =B19*303.396333333333/100 -> 303.39633 | R19: =B19*0.848/100 -> 0.848 | S19: =B19*190.338666666667/100 -> 190.33867 | T19: =B19*143.294/100 -> 143.294 | U19: =B19*0.089/100 -> 0.089 | V19: =B19*0.675666666666667/100 -> 0.67566667 | W19: Tr | X19: =B19*0.153333333333333/100 -> 0.15333333 | Y19: =B19*0.0566666666666667/100 -> 0.056666667 | Z19: Tr | AA19: Tr | AB19: Tr
A20: Bolo, pronto, milho | B20: 100 | C20: =B20*311.387/100 -> 311.387 | D20: =B20*4.80416666666667/100 -> 4.8041667 | E20: =B20*12.415/100 -> 12.415 | F20: =B20*4.5/100 -> 4.5 | G20: =B20*3.9/100 -> 3.9 | H20: =B20*1.5/100 -> 1.5 | I20: =B20*1.38/100 -> 1.38 | J20: =B20*0.08/100 -> 0.08 | K20: =B20*81.6873333333333/100 -> 81.687333 | L20: =B20*45.1088333333333/100 -> 45.108833 | M20: =B20*0.71/100 -> 0.71 | N20: =B20*82.5846666666667/100 -> 82.584667 | O20: =B20*10.249/100 -> 10.249 | P20: =B20*0.107666666666667/100 -> 0.10766667 | Q20: =B20*128.196333333333/100 -> 128.19633 | R20: =B20*0.65/100 -> 0.65 | S20: =B20*133.811/100 -> 133.811 | T20: =B20*118.427333333333/100 -> 118.42733 | U20: =B20*0.04/100 -> 0.04 | V20: =B20*0.435/100 -> 0.435 | W20: =B20*56.8866666666667/100 -> 56.886667 | X20: =B20*0.11/100 -> 0.11 | Y20: =B20*0.05/100 -> 0.05 | Z20: Tr | AA20: Tr | AB20: Tr
A21: Canjica, branca, crua | B21: 100 | C21: =B21*357.60259/100 -> 357.60259 | D21: =B21*7.2/100 -> 7.2 | E21: =B21*0.971/100 -> 0.971 | F21: =B21*0.3/100 -> 0.3 | G21: =B21*0.2/100 -> 0.2 | H21: =B21*0.4/100 -> 0.4 | I21: =B21*0.38/100 -> 0.38 | J21: =B21*0.01/100 -> 0.01 | K21: NA | L21: =B21*78.061/100 -> 78.061 | M21: =B21*5.49933333333333/100 -> 5.4993333 | N21: =B21*1.96466666666667/100 -> 1.9646667 | O21: =B21*12.325/100 -> 12.325 | P21: =B21*0.0863333333333333/100 -> 0.086333333 | Q21: =B21*48.498/100 -> 48.498 | R21: =B21*0.321666666666667/100 -> 0.32166667 | S21: =B21*0.789666666666667/100 -> 0.78966667 | T21: =B21*92.9473333333333/100 -> 92.947333 | U21: =B21*0.045/100 -> 0.045 | V21: =B21*0.362333333333333/100 -> 0.36233333 | W21: NA | X21: Tr | Y21: Tr | Z21: Tr | AA21: Tr | AB21: Tr
A22: Canjica, com leite integral | B22: 100 | C22: =B22*112.456777220465/100 -> 112.45678 | D22: =B22*2.36060004234314/100 -> 2.3606 | E22: =B22*1.24433333333333/100 -> 1.2443333 | F22: =B22*0.603666666666667/100 -> 0.60366667 | G22: =B22*0.365666666666667/100 -> 0.36566667 | H22: =B22*0.149666666666667/100 -> 0.14966667 | I22: =B22*0.149666666666667/100 -> 0.14966667 | J22: Tr | K22: =B22*1.35066666666667/100 -> 1.3506667 | L22: =B22*23.6277332909902/100 -> 23.627733 | M22: =B22*1.21666666666667/100 -> 1.2166667 | N22: =B22*42.5626666666667/100 -> 42.562667 | O22: =B22*5.83833333333333/100 -> 5.8383333 | P22: =B22*0.02/100 -> 0.02 | Q22: =B22*40.5833333333333/100 -> 40.583333 | R22: =B22*0.056/100 -> 0.056 | S22: =B22*27.5866666666667/100 -> 27.586667 | T22: =B22*69.809/100 -> 69.809 | U22: =B22*0.0256666666666667/100 -> 0.025666667 | V22: =B22*0.278/100 -> 0.278 | W22: Tr | X22: Tr | Y22: =B22*0.04/100 -> 0.04 | Z22: Tr | AA22: Tr | AB22: Tr
A23: Cereais, milho, flocos, com sal | B23: 100 | C23: =B23*369.59975/100 -> 369.59975 | D23: =B23*7.29166666666667/100 -> 7.2916667 | E23: =B23*1.60333333333333/100 -> 1.6033333 | F23: =B23*0.5/100 -> 0.5 | G23: =B23*0.6/100 -> 0.6 | H23: =B23*0.9/100 -> 0.9 | I23: =B23*0.89/100 -> 0.89 | J23: =B23*0.03/100 -> 0.03 | K23: NA | L23: =B23*80.835/100 -> 80.835 | M23: =B23*5.29333333333333/100 -> 5.2933333 | N23: =B23*1.81366666666667/100 -> 1.8136667 | O23: =B23*20.096/100 -> 20.096 | P23: Tr | Q23: =B23*90.7703333333333/100 -> 90.770333 | R23: =B23*0.524333333333333/100 -> 0.52433333 | S23: =B23*271.737666666667/100 -> 271.73767 | T23: =B23*68.66/100 -> 68.66 | U23: Tr | V23: =B23*0.611/100 -> 0.611 | W23: NA | X23: =B23*0.12/100 -> 0.12 | Y23: Tr | Z23: =B23*0.06/100 -> 0.06 | AA23: Tr | AB23: Tr
A24: Cereais, milho, flocos, sem sal | B24: 100 | C24: =B24*363.338316666667/100 -> 363.33832 | D24: =B24*6.875/100 -> 6.875 | E24: =B24*1.18333333333333/100 -> 1.1833333 | F24: =B24*0.3/100 -> 0.3 | G24: =B24*0.3/100 -> 0.3 | H24: =B24*0.6/100 -> 0.6 | I24: =B24*0.6/100 -> 0.6 | J24: =B24*0.02/100 -> 0.02 | K24: NA | L24: =B24*80.4483333333333/100 -> 80.448333 | M24: =B24*1.83666666666667/100 -> 1.8366667 | N24: =B24*1.97466666666667/100 -> 1.9746667 | O24: =B24*16.5486666666667/100 -> 16.548667 | P24: Tr | Q24: =B24*58.3596666666667/100 -> 58.359667 | R24: =B24*1.69333333333333/100 -> 1.6933333 | S24: =B24*30.9703333333333/100 -> 30.970333 | T24: =B24*28.6973333333333/100 -> 28.697333 | U24: =B24*0.240333333333333/100 -> 0.24033333 | V24: =B24*0.325666666666667/100 -> 0.32566667 | W24: NA | X24: =B24*0.05/100 -> 0.05 | Y24: Tr | Z24: =B24*0.04/100 -> 0.04 | AA24: Tr | AB24: Tr
A25: Cereais, mingau, milho, infantil | B25: 100 | C25: =B25*394.42752173913/100 -> 394.42752 | D25: =B25*6.43115942028986/100 -> 6.4311594 | E25: =B25*1.09333333333333/100 -> 1.0933333 | F25: =B25*0.3/100 -> 0.3 | G25: =B25*0.3/100 -> 0.3 | H25: =B25*0.5/100 -> 0.5 | I25: =B25*0.45/100 -> 0.45 | J25: =B25*0.01/100 -> 0.01 | K25: NA | L25: =B25*87.2655072463768/100 -> 87.265507 | M25: =B25*3.21333333333333/100 -> 3.2133333 | N25: =B25*218.806666666667/100 -> 218.80667 | O25: =B25*16.03/100 -> 16.03 | P25: =B25*0.106333333333333/100 -> 0.10633333 | Q25: =B25*169.163333333333/100 -> 169.16333 | R25: =B25*3.03/100 -> 3.03 | S25: =B25*399.403333333333/100 -> 399.40333 | T25: =B25*82.0166666666667/100 -> 82.016667 | U25: =B25*0.0433333333333333/100 -> 0.043333333 | V25: =B25*0.363333333333333/100 -> 0.36333333 | W25: =B25*21.4166666666667/100 -> 21.416667 | X25: =B25*3.72333333333333/100 -> 3.7233333 | Y25: =B25*0.466666666666667/100 -> 0.46666667 | Z25: =B25*5.07666666666667/100 -> 5.0766667 | AA25: =B25*24.1633333333333/100 -> 24.163333 | AB25: =B25*109.366666666667/100 -> 109.36667
A26: Cereais, mistura para vitamina, trigo, cevada e aveia | B26: 100 | C26: =B26*381.133333333333/100 -> 381.13333 | D26: =B26*8.89583333333333/100 -> 8.8958333 | E26: =B26*2.12/100 -> 2.12 | F26: =B26*0.5/100 -> 0.5 | G26: =B26*0.4/100 -> 0.4 | H26: =B26*1/100 -> 1 | I26: =B26*0.93/100 -> 0.93 | J26: =B26*0.06/100 -> 0.06 | K26: NA | L26: =B26*81.6175/100 -> 81.6175 | M26: =B26*4.98333333333333/100 -> 4.9833333 | N26: =B26*584.251333333333/100 -> 584.25133 | O26: =B26*72.268/100 -> 72.268 | P26: =B26*2.284/100 -> 2.284 | Q26: =B26*515.036/100 -> 515.036 | R26: =B26*12.6413333333333/100 -> 12.641333 | S26: =B26*1163.257/100 -> 1163.257 | T26: =B26*244.361/100 -> 244.361 | U26: =B26*0.206333333333333/100 -> 0.20633333 | V26: =B26*2.02233333333333/100 -> 2.0223333 | W26: Tr | X26: =B26*0.76/100 -> 0.76 | Y26: =B26*0.876666666666667/100 -> 0.87666667 | Z26: =B26*1.48666666666667/100 -> 1.4866667 | AA26: =B26*7.45666666666667/100 -> 7.4566667 | AB26: =B26*13.1066666666667/100 -> 13.106667
A27: Cereal matinal, milho | B27: 100 | C27: =B27*365.354163768116/100 -> 365.35416 | D27: =B27*7.15579710144928/100 -> 7.1557971 | E27: =B27*0.956666666666667/100 -> 0.95666667 | F27: =B27*0.356666666666667/100 -> 0.35666667 | G27: =B27*0.319666666666667/100 -> 0.31966667 | H27: =B27*0.328666666666667/100 -> 0.32866667 | I27: =B27*0.313333333333333/100 -> 0.31333333 | J27: Tr | K27: NA | L27: =B27*83.8242028985507/100 -> 83.824203 | M27: =B27*4.11666666666667/100 -> 4.1166667 | N27: =B27*142.923333333333/100 -> 142.92333 | O27: =B27*10.9333333333333/100 -> 10.933333 | P27: =B27*0.059/100 -> 0.059 | Q27: =B27*100.8/100 -> 100.8 | R27: =B27*3.05/100 -> 3.05 | S27: =B27*654.543333333333/100 -> 654.54333 | T27: =B27*83.0866666666667/100 -> 83.086667 | U27: =B27*0.06/100 -> 0.06 | V27: =B27*7.63/100 -> 7.63 | W27: NA | X27: =B27*0.76/100 -> 0.76 | Y27: =B27*1.02/100 -> 1.02 | Z27: =B27*2.24666666666667/100 -> 2.2466667 | AA27: =B27*11.04/100 -> 11.04 | AB27: =B27*17.2933333333333/100 -> 17.293333
A28: Cereal matinal, milho, açúcar | B28: 100 | C28: =B28*376.555253623188/100 -> 376.55525 | D28: =B28*4.74275362318841/100 -> 4.7427536 | E28: =B28*0.666666666666667/100 -> 0.66666667 | F28: =B28*0.23/100 -> 0.23 | G28: =B28*0.286333333333333/100 -> 0.28633333 | H28: =B28*0.329/100 -> 0.329 | I28: =B28*0.329/100 -> 0.329 | J28: Tr | K28: NA | L28: =B28*88.8405797101449/100 -> 88.84058 | M28: =B28*2.10666666666667/100 -> 2.1066667 | N28: =B28*56.4233333333333/100 -> 56.423333 | O28: =B28*7.94/100 -> 7.94 | P28: =B28*0.134333333333333/100 -> 0.13433333 | Q28: =B28*43.18/100 -> 43.18 | R28: =B28*3.90333333333333/100 -> 3.9033333 | S28: =B28*405.313333333333/100 -> 405.31333 | T28: =B28*51.5966666666667/100 -> 51.596667 | U28: =B28*0.04/100 -> 0.04 | V28: =B28*8.48/100 -> 8.48 | W28: NA | X28: =B28*0.726666666666667/100 -> 0.72666667 | Y28: =B28*1.11/100 -> 1.11 | Z28: =B28*0.786666666666667/100 -> 0.78666667 | AA28: =B28*10.1333333333333/100 -> 10.133333 | AB28: =B28*14.55/100 -> 14.55
A29: Creme de arroz, pó | B29: 100 | C29: =B29*386.001190336398/100 -> 386.00119 | D29: =B29*7.02694977474213/100 -> 7.0269498 | E29: =B29*1.226/100 -> 1.226 | F29: =B29*0.4/100 -> 0.4 | G29: =B29*0.3/100 -> 0.3 | H29: =B29*0.4/100 -> 0.4 | I29: =B29*0.43/100 -> 0.43 | J29: =B29*0.01/100 -> 0.01 | K29: NA | L29: =B29*83.8693835585912/100 -> 83.869384 | M29: =B29*1.07133333333333/100 -> 1.0713333 | N29: =B29*7.08533333333333/100 -> 7.0853333 | O29: =B29*50.5033333333333/100 -> 50.503333 | P29: =B29*1.23733333333333/100 -> 1.2373333 | Q29: =B29*153.02/100 -> 153.02 | R29: =B29*0.632333333333333/100 -> 0.63233333 | S29: =B29*1.03033333333333/100 -> 1.0303333 | T29: =B29*114.680333333333/100 -> 114.68033 | U29: =B29*0.038/100 -> 0.038 | V29: =B29*1.86366666666667/100 -> 1.8636667 | W29: NA | X29: =B29*0.216666666666667/100 -> 0.21666667 | Y29: Tr | Z29: =B29*0.0533333333333333/100 -> 0.053333333 | AA29: Tr | AB29: Tr
A30: Creme de milho, pó | B30: 100 | C30: =B30*333.034192670544/100 -> 333.03419 | D30: =B30*4.82083333333333/100 -> 4.8208333 | E30: =B30*1.63933333333333/100 -> 1.6393333 | F30: =B30*0.3/100 -> 0.3 | G30: =B30*0.5/100 -> 0.5 | H30: =B30*0.8/100 -> 0.8 | I30: =B30*0.75/100 -> 0.75 | J30: =B30*0.02/100 -> 0.02 | K30: NA | L30: =B30*86.1485/100 -> 86.1485 | M30: =B30*3.72233333333333/100 -> 3.7223333 | N30: =B30*323.163333333333/100 -> 323.16333 | O30: =B30*30.0623333333333/100 -> 30.062333 | P30: =B30*0.2/100 -> 0.2 | Q30: =B30*303.266666666667/100 -> 303.26667 | R30: =B30*4.257/100 -> 4.257 | S30: =B30*593.793666666667/100 -> 593.79367 | T30: =B30*165.723666666667/100 -> 165.72367 | U30: =B30*0.0426666666666667/100 -> 0.042666667 | V30: =B30*0.780666666666667/100 -> 0.78066667 | W30: NA | X30: =B30*0.74/100 -> 0.74 | Y30: Tr | Z30: =B30*2.05333333333333/100 -> 2.0533333 | AA30: Tr | AB30: =B30*96.34/100 -> 96.34
A31: Curau, milho verde | B31: 100 | C31: =B31*78.4338183136558/100 -> 78.433818 | D31: =B31*2.36060004234314/100 -> 2.3606 | E31: =B31*1.637/100 -> 1.637 | F31: =B31*0.817333333333333/100 -> 0.81733333 | G31: =B31*0.468/100 -> 0.468 | H31: =B31*0.174666666666667/100 -> 0.17466667 | I31: =B31*0.174666666666667/100 -> 0.17466667 | J31: Tr | K31: =B31*4.742/100 -> 4.742 | L31: =B31*13.9443999576569/100 -> 13.9444 | M31: =B31*0.456666666666667/100 -> 0.45666667 | N31: =B31*52.596/100 -> 52.596 | O31: =B31*15.9613333333333/100 -> 15.961333 | P31: =B31*0.0556666666666667/100 -> 0.055666667 | Q31: =B31*74.6563333333333/100 -> 74.656333 | R31: =B31*0.449333333333333/100 -> 0.44933333 | S31: =B31*20.512/100 -> 20.512 | T31: =B31*161.842333333333/100 -> 161.84233 | U31: =B31*0.0253333333333333/100 -> 0.025333333 | V31: =B31*0.4/100 -> 0.4 | W31: =B31*12.07/100 -> 12.07 | X31: =B31*0.0366666666666667/100 -> 0.036666667 | Y31: =B31*0.07/100 -> 0.07 | Z31: Tr | AA31: Tr | AB31: Tr
A32: Curau, milho verde, mistura para | B32: 100 | C32: =B32*402.286577435315/100 -> 402.28658 | D32: =B32*2.22291666666667/100 -> 2.2229167 | E32: =B32*13.3713333333333/100 -> 13.371333 | F32: =B32*3/100 -> 3 | G32: =B32*4.9/100 -> 4.9 | H32: =B32*1.4/100 -> 1.4 | I32: =B32*1.38/100 -> 1.38 | J32: =B32*0.03/100 -> 0.03 | K32: NA | L32: =B32*79.8164166666667/100 -> 79.816417 | M32: =B32*2.52266666666667/100 -> 2.5226667 | N32: =B32*30.878/100 -> 30.878 | O32: =B32*8.50066666666667/100 -> 8.5006667 | P32: =B32*0.0546666666666667/100 -> 0.054666667 | Q32: =B32*44.619/100 -> 44.619 | R32: =B32*0.862666666666667/100 -> 0.86266667 | S32: =B32*222.925666666667/100 -> 222.92567 | T32: =B32*55.3353333333333/100 -> 55.335333 | U32: =B32*0.0293333333333333/100 -> 0.029333333 | V32: =B32*0.240666666666667/100 -> 0.24066667 | W32: NA | X32: =B32*0.133333333333333/100 -> 0.13333333 | Y32: Tr | Z32: Tr | AA32: Tr | AB32: Tr
A33: Farinha, de arroz, enriquecida | B33: 100 | C33: =B33*363.056480181223/100 -> 363.05648 | D33: =B33*1.26933329264323/100 -> 1.2693333 | E33: =B33*0.3/100 -> 0.3 | F33: =B33*0.2/100 -> 0.2 | G33: =B33*0.1/100 -> 0.1 | H33: =B33*0.2/100 -> 0.2 | I33: =B33*0.17/100 -> 0.17 | J33: =B33*0.01/100 -> 0.01 | K33: NA | L33: =B33*85.5040000406901/100 -> 85.504 | M33: =B33*0.58/100 -> 0.58 | N33: =B33*1.12266666666667/100 -> 1.1226667 | O33: =B33*4.3/100 -> 4.3 | P33: =B33*0.0423333333333333/100 -> 0.042333333 | Q33: =B33*35.9586666666667/100 -> 35.958667 | R33: =B33*31.3833333333333/100 -> 31.383333 | S33: =B33*17.1016666666667/100 -> 17.101667 | T33: =B33*12.5406666666667/100 -> 12.540667 | U33: Tr | V33: =B33*8.48/100 -> 8.48 | W33: NA | X33: =B33*3.23333333333333/100 -> 3.2333333 | Y33: Tr | Z33: =B33*3.46666666666667/100 -> 3.4666667 | AA33: =B33*24.4233333333333/100 -> 24.423333 | AB33: =B33*173.586666666667/100 -> 173.58667
A34: Farinha, de centeio, integral | B34: 100 | C34: =B34*335.777662799327/100 -> 335.77766 | D34: =B34*12.515066502889/100 -> 12.515067 | E34: =B34*1.75333333333333/100 -> 1.7533333 | F34: =B34*0.3/100 -> 0.3 | G34: =B34*0.3/100 -> 0.3 | H34: =B34*0.8/100 -> 0.8 | I34: =B34*0.73/100 -> 0.73 | K34: NA | L34: =B34*73.2982668304443/100 -> 73.298267 | M34: =B34*15.48/100 -> 15.48 | N34: =B34*33.9166666666667/100 -> 33.916667 | O34: =B34*120.233333333333/100 -> 120.23333 | P34: =B34*3.85666666666667/100 -> 3.8566667 | Q34: =B34*339.986666666667/100 -> 339.98667 | R34: =B34*4.73/100 -> 4.73 | S34: =B34*41.3766666666667/100 -> 41.376667 | T34: =B34*333.62/100 -> 333.62 | U34: =B34*0.563333333333333/100 -> 0.56333333 | V34: =B34*2.66333333333333/100 -> 2.6633333 | W34: NA | X34: =B34*0.286666666666667/100 -> 0.28666667 | Y34: =B34*0.03/100 -> 0.03 | Z34: =B34*0.08/100 -> 0.08 | AA34: Tr | AB34: Tr
A35: Farinha, de milho, amarela | B35: 100 | C35: =B35*350.58693322738/100 -> 350.58693 | D35: =B35*7.1875/100 -> 7.1875 | E35: =B35*1.46666666666667/100 -> 1.4666667 | F35: =B35*0.4/100 -> 0.4 | G35: =B35*0.4/100 -> 0.4 | H35: =B35*0.6/100 -> 0.6 | I35: =B35*0.63/100 -> 0.63 | J35: =B35*0.02/100 -> 0.02 | K35: NA | L35: =B35*79.0791666666667/100 -> 79.079167 | M35: =B35*5.49/100 -> 5.49 | N35: =B35*1.285/100 -> 1.285 | O35: =B35*30.955/100 -> 30.955 | P35: Tr | Q35: =B35*84.2213333333333/100 -> 84.221333 | R35: =B35*2.25266666666667/100 -> 2.2526667 | S35: =B35*44.9323333333333/100 -> 44.932333 | T35: =B35*57.8536666666667/100 -> 57.853667 | U35: =B35*0.266666666666667/100 -> 0.26666667 | V35: =B35*0.598333333333333/100 -> 0.59833333 | W35: NA | X35: =B35*0.253333333333333/100 -> 0.25333333 | Y35: Tr | Z35: =B35*0.253333333333333/100 -> 0.25333333 | AA35: Tr | AB35: Tr
A36: Farinha, de rosca | B36: 100 | C36: =B36*370.578096666667/100 -> 370.5781 | D36: =B36*11.3809996191661/100 -> 11.381 | E36: =B36*1.46333333333333/100 -> 1.4633333 | F36: =B36*0.6/100 -> 0.6 | G36: =B36*0.4/100 -> 0.4 | H36: =B36*0.8/100 -> 0.8 | I36: =B36*0.74/100 -> 0.74 | J36: =B36*0.05/100 -> 0.05 | K36: NA | L36: =B36*75.7856666666667/100 -> 75.785667 | M36: =B36*4.82333333333333/100 -> 4.8233333 | N36: =B36*35.2993333333333/100 -> 35.299333 | O36: =B36*56.8796666666667/100 -> 56.879667 | P36: =B36*1.62066666666667/100 -> 1.6206667 | Q36: =B36*194.958333333333/100 -> 194.95833 | R36: =B36*6.73366666666667/100 -> 6.7336667 | S36: =B36*332.5/100 -> 332.5 | T36: =B36*212.144/100 -> 212.144 | U36: =B36*0.263/100 -> 0.263 | V36: =B36*1.67133333333333/100 -> 1.6713333 | W36: NA | X36: =B36*0.253333333333333/100 -> 0.25333333 | Y36: Tr | Z36: =B36*0.09/100 -> 0.09 | AA36: Tr | AB36: Tr
A37: Farinha, de trigo | B37: 100 | C37: =B37*360.472978550725/100 -> 360.47298 | D37: =B37*9.79078260869565/100 -> 9.7907826 | E37: =B37*1.36666666666667/100 -> 1.3666667 | F37: =B37*0.31/100 -> 0.31 | G37: =B37*0.155/100 -> 0.155 | H37: =B37*0.445/100 -> 0.445 | I37: =B37*0.431/100 -> 0.431 | J37: =B37*0.01/100 -> 0.01 | K37: NA | L37: =B37*75.0925507246377/100 -> 75.092551 | M37: =B37*2.34666666666667/100 -> 2.3466667 | N37: =B37*17.8633333333333/100 -> 17.863333 | O37: =B37*31.0033333333333/100 -> 31.003333 | P37: =B37*0.460333333333333/100 -> 0.46033333 | Q37: =B37*114.74/100 -> 114.74 | R37: =B37*0.95/100 -> 0.95 | S37: =B37*0.736666666666667/100 -> 0.73666667 | T37: =B37*151.366666666667/100 -> 151.36667 | U37: =B37*0.15/100 -> 0.15 | V37: =B37*0.826666666666667/100 -> 0.82666667 | W37: NA | X37: =B37*0.313333333333333/100 -> 0.31333333 | Y37: Tr | Z37: Tr | AA37: =B37*0.89/100 -> 0.89 | AB37: Tr
A38: Farinha, láctea, de cereais | B38: 100 | C38: =B38*414.850517391304/100 -> 414.85052 | D38: =B38*11.8791304347826/100 -> 11.87913 | E38: =B38*5.79/100 -> 5.79 | F38: =B38*3.3/100 -> 3.3 | G38: =B38*1.4/100 -> 1.4 | H38: =B38*0.6/100 -> 0.6 | I38: =B38*0.59/100 -> 0.59 | J38: =B38*0.03/100 -> 0.03 | K38: =B38*11.2718/100 -> 11.2718 | L38: =B38*77.7708695652174/100 -> 77.77087 | M38: =B38*1.94/100 -> 1.94 | N38: =B38*196.063333333333/100 -> 196.06333 | O38: =B38*57.6866666666667/100 -> 57.686667 | P38: =B38*1.489/100 -> 1.489 | Q38: =B38*296.443333333333/100 -> 296.44333 | R38: =B38*8.72333333333333/100 -> 8.7233333 | S38: =B38*125.073333333333/100 -> 125.07333 | T38: =B38*365.603333333333/100 -> 365.60333 | U38: =B38*0.193333333333333/100 -> 0.19333333 | V38: =B38*1.72666666666667/100 -> 1.7266667 | W38: =B38*492.246666666667/100 -> 492.24667 | X38: =B38*1.43/100 -> 1.43 | Y38: =B38*1.13333333333333/100 -> 1.1333333 | Z38: =B38*1.13666666666667/100 -> 1.1366667 | AA38: =B38*9.5/100 -> 9.5 | AB38: =B38*24.31/100 -> 24.31
A39: Lasanha, massa fresca, cozida | B39: 100 | C39: =B39*163.763666666667/100 -> 163.76367 | D39: =B39*5.8125/100 -> 5.8125 | E39: =B39*1.15833333333333/100 -> 1.1583333 | F39: =B39*0.6/100 -> 0.6 | G39: =B39*0.4/100 -> 0.4 | H39: =B39*0.1/100 -> 0.1 | I39: =B39*0.1/100 -> 0.1 | K39: NA | L39: =B39*32.5221666666667/100 -> 32.522167 | M39: =B39*1.63633333333333/100 -> 1.6363333 | N39: =B39*9.97166666666667/100 -> 9.9716667 | O39: =B39*3.539/100 -> 3.539 | P39: =B39*0.195/100 -> 0.195 | Q39: =B39*42.384/100 -> 42.384 | R39: =B39*1.18866666666667/100 -> 1.1886667 | S39: =B39*206.769333333333/100 -> 206.76933 | T39: =B39*53.9146666666667/100 -> 53.914667 | U39: =B39*0.0706666666666667/100 -> 0.070666667 | V39: =B39*0.405/100 -> 0.405 | W39: NA | X39: =B39*0.04/100 -> 0.04 | Y39: Tr | Z39: Tr | AA39: =B39*3.96/100 -> 3.96
